<?xml version="1.0" ?>
<sdf version="1.10">
    <!-- Defining the model that we are adding into the scene, that in this case it will be a car -->
    <!--* CAR MODEL  -->
    <model name='robot'>

        <!--* CHASSIS  -->
        <link name='chassis'>
            <pose>-0.5 0 0.4 0 0 0</pose>    <!-- its pose relative to the model -->
            
            <inertial> <!--inertial properties of the link mass, inertia matix-->
                <mass>1.14395</mass>
                <inertia>
                    <ixx>0.095329</ixx>
                    <ixy>0</ixy>
                    <ixz>0</ixz>
                    <iyy>0.381317</iyy>
                    <iyz>0</iyz>
                    <izz>0.476646</izz>
                </inertia>
            </inertial>

            <visual name='visual_chassis'>
                <geometry>
                    <box>
                        <size>2.0 1.0 0.5</size>
                    </box>
                </geometry>
                <!--let's add color to our link-->
                <material>
                    <ambient>0.0 0.0 1.0 1</ambient>
                    <diffuse>0.0 0.0 1.0 1</diffuse>
                    <specular>0.0 0.0 1.0 1</specular>
                </material>
            </visual>

            <collision name='collision_chassis'>
                <geometry>
                    <box>
                        <size>2.0 1.0 0.5</size>
                    </box>
                </geometry>
            </collision>
        </link>


        <!--* LEFT WHEEL  -->
        <link name='left_wheel'>
            <pose relative_to="chassis">-0.5 0.6 0 -1.5707 0 0</pose>
            <inertial>
                <mass>1</mass>
                <inertia>
                    <ixx>0.043333</ixx>
                    <ixy>0</ixy>
                    <ixz>0</ixz>
                    <iyy>0.043333</iyy>
                    <iyz>0</iyz>
                    <izz>0.08</izz>
                </inertia>
            </inertial>

            <visual name='visual_left_wheel'>
                <geometry>
                    <cylinder>
                        <radius>0.4</radius>
                        <length>0.2</length>
                    </cylinder>
                </geometry>
                <material>
                    <ambient>1.0 0.0 0.0 1</ambient>
                    <diffuse>1.0 0.0 0.0 1</diffuse>
                    <specular>1.0 0.0 0.0 1</specular>
                </material>
            </visual>
            <collision name='collision_left_wheel'>
                <geometry>
                    <cylinder>
                        <radius>0.4</radius>
                        <length>0.2</length>
                    </cylinder>
                </geometry>
            </collision>
        </link>

        <!--* LEFT WHEEL JOINT -->
        <joint name='left_wheel_joint' type='revolute'>
            <parent>chassis</parent>
            <child>left_wheel</child>
            <axis>
            <xyz>0 0 1</xyz>
            <limit>
                <lower>-1.79769e+308</lower>
                <upper>1.79769e+308</upper>
            </limit>
            </axis>
        </joint>

        <!--* RIGHT WHEEL -->
        <link name='right_wheel'>
            <pose relative_to="chassis">-0.5 -0.6 0 -1.5707 0 0</pose> <!--angles are in radian-->
            <inertial>
                <mass>1</mass>
                <inertia>
                    <ixx>0.043333</ixx>
                    <ixy>0</ixy>
                    <ixz>0</ixz>
                    <iyy>0.043333</iyy>
                    <iyz>0</iyz>
                    <izz>0.08</izz>
                </inertia>
            </inertial>
            <visual name='visual_right_wheel'>
                <geometry>
                    <cylinder>
                        <radius>0.4</radius>
                        <length>0.2</length>
                    </cylinder>
                </geometry>
                <material>
                    <ambient>1.0 0.0 0.0 1</ambient>
                    <diffuse>1.0 0.0 0.0 1</diffuse>
                    <specular>1.0 0.0 0.0 1</specular>
                </material>
            </visual>
            <collision name='collision_right_wheel'>
                <geometry>
                    <cylinder>
                        <radius>0.4</radius>
                        <length>0.2</length>
                    </cylinder>
                </geometry>
            </collision>
        </link>

        <!--* RIGHT WHEEL JOINT -->
        <joint name='right_wheel_joint' type='revolute'>
            <parent>chassis</parent>
            <child>right_wheel</child>
            <axis>
            <xyz>0 0 1</xyz>
            <limit>
                <lower>-1.79769e+308</lower>
                <upper>1.79769e+308</upper>
            </limit>
            </axis>
        </joint>

        
        <!--*CASTER WHEEL-->
        <link name='caster'>
            <pose relative_to="chassis">0.8 0 -0.35 0 0 0</pose>
            <inertial>
                <mass>1</mass>
                <inertia>
                    <ixx>0.016</ixx>
                    <ixy>0</ixy>
                    <ixz>0</ixz>
                    <iyy>0.016</iyy>
                    <iyz>0</iyz>
                    <izz>0.016</izz>
                </inertia>
            </inertial>
            <visual name='visual'>
                <geometry>
                    <sphere>
                        <radius>0.2</radius>
                    </sphere>
                </geometry>
                <material>
                    <ambient>0.0 1 0.0 1</ambient>
                    <diffuse>0.0 1 0.0 1</diffuse>
                    <specular>0.0 1 0.0 1</specular>
                </material>
            </visual>
            <collision name='collision'>
                <geometry>
                    <sphere>
                        <radius>0.2</radius>
                    </sphere>
                </geometry>
            </collision>
        </link>

        <!--*CASTER WHEEL JOINT-->
        <joint name='caster_wheel_joint' type='revolute'>
            <parent>chassis</parent>
            <child>caster</child>
            <axis>
            <xyz>0 0 1</xyz>
            <limit>
                <lower>-1.79769e+308</lower>
                <upper>1.79769e+308</upper>
            </limit>
            </axis>
        </joint>

        <!-- LiDAR SENSOR -->
        <!-- Different from the simulation, here we need to add a link for the sensor, and them put the sensor tag -->
        <link name="lidar_link">
            <pose>0.8 0 0.5 0 0 0</pose>
            <inertial>
            <mass>0.1</mass>
            <inertia>
                <ixx>0.000166667</ixx>
                <iyy>0.000166667</iyy>
                <izz>0.000166667</izz>
            </inertia>
            </inertial>
            <collision name="collision">
            <geometry>
                <box>
                <size>0.1 0.1 0.1</size>
                </box>
            </geometry>
            </collision>
            <visual name="visual">
            <geometry>
                <box>
                <size>0.1 0.1 0.1</size>
                </box>
            </geometry>
            </visual>
            <sensor name='gpu_lidar' type='gpu_lidar'>
            <pose>0 0 0 0 0 0</pose>
            <topic>scan</topic>
            <gz_frame_id>robot/lidar_link</gz_frame_id>
            <update_rate>10</update_rate>
            <lidar>
                <scan>
                <horizontal>
                    <samples>640</samples>
                    <resolution>1</resolution>
                    <min_angle>-1.396263</min_angle>
                    <max_angle>1.396263</max_angle>
                </horizontal>
                <vertical>
                    <samples>1</samples>
                    <resolution>1</resolution>
                    <min_angle>0.0</min_angle>
                    <max_angle>0.0</max_angle>
                </vertical>
                </scan>
                <range>
                <min>0.08</min>
                <max>10.0</max>
                <resolution>0.01</resolution>
                </range>
            </lidar>
            <visualize>true</visualize>
            </sensor>
        </link>


        <link name="camera_link">
        <pose>0.5 0.5 0.5 0 0 0</pose>

        <inertial>
            <mass>0.1</mass>
            <inertia>
            <ixx>0.000166667</ixx>
            <iyy>0.000166667</iyy>
            <izz>0.000166667</izz>
            </inertia>
        </inertial>

        <collision name="camera_collision">
            <geometry>
            <box>
                <size>0.1 0.1 0.1</size>
            </box>
            </geometry>
        </collision>

        <visual name="camera_visual">
            <geometry>
            <box>
                <size>0.1 0.1 0.1</size>
            </box>
            </geometry>
        </visual>

        <!-- Camera sensor -->
        <sensor name="camera_front" type="camera">
         <pose>0.5 0.5 0.5 0 0 0</pose>
         <always_on>1</always_on>
         <update_rate>25</update_rate>
         <camera name="camera_front">
           <horizontal_fov>1.658</horizontal_fov>
           <lens>
             <intrinsics>
               <!-- fx = fy = width / ( 2 * tan (hfov / 2 ) ) -->
               <fx>329.9</fx>
               <fy>329.9</fy>
               <!-- cx = ( width - 1 ) / 2 -->
               <cx>359.5</cx>
               <!-- cy = ( height - 1 ) / 2 -->
               <cy>539.5</cy>
               <s>0</s>
             </intrinsics>
           </lens>
           <distortion>
             <k1>0.0</k1>
             <k2>0.0</k2>
             <k3>0.0</k3>
             <p1>0.0</p1>
             <p2>0.0</p2>
             <center>0.5 0.5</center>
           </distortion>
           <image>
             <width>720</width>
             <height>1080</height>
             <format>R8G8B8</format>
           </image>
           <clip>
             <near>0.01</near>
             <far>300</far>
           </clip>
           <noise>
             <type>gaussian</type>
             <mean>0</mean>
             <stddev>0.007</stddev>
           </noise>
         </camera>
       </sensor>
        </link>


        <joint name="camera_joint" type="fixed">
            <parent>chassis</parent>
            <child>camera_link</child>
        </joint>



        <joint name='lidar_joint' type='fixed'>
            <parent>chassis</parent>
            <child>lidar_link</child>
        </joint>


        <!--* Add o plugin enable diff drive movement   -->
        <plugin
            filename="gz-sim-diff-drive-system"
            name="gz::sim::systems::DiffDrive">
            <left_joint>left_wheel_joint</left_joint>
            <right_joint>right_wheel_joint</right_joint>
            <wheel_separation>1.2</wheel_separation>
            <wheel_radius>0.4</wheel_radius>
            <odom_publish_frequency>1</odom_publish_frequency>
            <topic>cmd_vel</topic>
        </plugin>
        

    </model>

</sdf>